Test
Error

transactor_permissioning
rest-api_1 exited with code 139

two_families
[2017-11-14 23:41:16.821 WARNING  route_handlers] Timed out while waiting for validator response

test_network_permissioning
[36mtest-network-permissioning_1  |[0m [32m[2017-11-13 20:39:39.819 INFO     cli][0m [37mInitiating graceful shutdown (press Ctrl+C again to force)[0m
[36mtest-network-permissioning_1  |[0m [32m[2017-11-13 20:39:39.820 INFO     cli][0m [37mInitiating graceful shutdown (press Ctrl+C again to force)[0m
[36mtest-network-permissioning_1  |[0m [31m[2017-11-13 20:39:39.826 ERROR    base_events][0m [37mTask was destroyed but it is pending!
[36mtest-network-permissioning_1  |[0m task: <Task pending coro=<StateDeltaSubscriberHandler._handle_disconnect() running at /project/sawtooth-core/rest_api/sawtooth_rest_api/state_delta_subscription_handler.py:173>>[0m
[36mtest-network-permissioning_1  |[0m /usr/lib/python3.5/asyncio/base_events.py:412: RuntimeWarning: coroutine 'StateDeltaSubscriberHandler._handle_disconnect' was never awaited
[36mtest-network-permissioning_1  |[0m   self._ready.clear()
[36mtest-network-permissioning_1  |[0m ======== Running on http://127.0.0.1:8081 ========
[36mtest-network-permissioning_1  |[0m (Press CTRL+C to quit)
[36mtest-network-permissioning_1  |[0m [31m[2017-11-13 20:39:39.829 ERROR    base_events][0m [37mTask was destroyed but it is pending!
[36mtest-network-permissioning_1  |[0m task: <Task pending coro=<StateDeltaSubscriberHandler._handle_disconnect() running at /project/sawtooth-core/rest_api/sawtooth_rest_api/state_delta_subscription_handler.py:173>>[0m
[36mtest-network-permissioning_1  |[0m /usr/lib/python3.5/asyncio/base_events.py:412: RuntimeWarning: coroutine 'StateDeltaSubscriberHandler._handle_disconnect' was never awaited
[36mtest-network-permissioning_1  |[0m   self._ready.clear()
[36mtest-network-permissioning_1  |[0m ======== Running on http://127.0.0.1:8080 ========
[36mtest-network-permissioning_1  |[0m (Press CTRL+C to quit)
[36mtest-network-permissioning_1  |[0m [32m[2017-11-13 20:39:41 INFO    core][0m [37mduring waiting for response on registration: the connection to the validator was lost[0m
[36mtest-network-permissioning_1  |[0m [32m[2017-11-13 20:39:41 INFO    core][0m [37mduring waiting for response on registration: the connection to the validator was lost[0m
[36mtest-network-permissioning_1  |[0m [32m[2017-11-13 20:39:41 INFO    core][0m [37mreregistering with validator[0m
[36mtest-network-permissioning_1  |[0m [32m[2017-11-13 20:39:41 INFO    core][0m [37mreregistering with validator[0m
[36mtest-network-permissioning_1  |[0m [32m[2017-11-13 20:39:49.838 INFO     executor][0m [37m735c923376c1ef1cdfe83cc6f5186a525a0d631178319c1194d331e05920a1ceaa9257c09a74c1272d81f236bd18c4a9521710f499ee1fa8be5389626f1e425b did not respond to the Ping, removing transaction processor.[0m
[36mtest-network-permissioning_1  |[0m [32m[2017-11-13 20:39:49.840 INFO     executor][0m [37m62f8962282585d9dd18d4aaae46e0a21eafae1c73632f9a36f6fd383334469be90ec35d1ea395ed1fbf462f6d7289987b3b2b76d6a44d91294c73420a9b01446 did not respond to the Ping, removing transaction processor.[0m
[36mtest-network-permissioning_1  |[0m Traceback (most recent call last):
[36mtest-network-permissioning_1  |[0m   File "/project/sawtooth-core/bin/sawtooth-validator", line 37, in <module>
[36mtest-network-permissioning_1  |[0m     main()
[36mtest-network-permissioning_1  |[0m   File "/project/sawtooth-core/validator/sawtooth_validator/server/cli.py", line 366, in main
[36mtest-network-permissioning_1  |[0m     validator.stop()
[36mtest-network-permissioning_1  |[0m   File "/project/sawtooth-core/validator/sawtooth_validator/server/core.py", line 356, in stop
[36mtest-network-permissioning_1  |[0m     self._executor.stop()
[36mtest-network-permissioning_1  |[0m   File "/project/sawtooth-core/validator/sawtooth_validator/execution/executor.py", line 439, in stop
[36mtest-network-permissioning_1  |[0m     self._executing_threadpool.shutdown(wait=True)
[36mtest-network-permissioning_1  |[0m   File "/usr/lib/python3.5/concurrent/futures/thread.py", line 139, in shutdown
[36mtest-network-permissioning_1  |[0m     t.join()
[36mtest-network-permissioning_1  |[0m   File "/usr/lib/python3.5/threading.py", line 1054, in join
[36mtest-network-permissioning_1  |[0m     self._wait_for_tstate_lock()
[36mtest-network-permissioning_1  |[0m   File "/usr/lib/python3.5/threading.py", line 1070, in _wait_for_tstate_lock
[36mtest-network-permissioning_1  |[0m     elif lock.acquire(block, timeout):
[36mtest-network-permissioning_1  |[0m KeyboardInterrupt
[36mtest-network-permissioning_1  |[0m [32m[2017-11-13 20:39:59.839 INFO     executor][0m [37m3dcb2a3657facb2dfddf7f33b28ed4c3787c0320a8ae3e9341724f99a2441b0665e44cd8c673e3f117e299d294c69d1aad8589752e45fcccc4f3717a646be364 did not respond to the Ping, removing transaction processor.[0m
[36mtest-network-permissioning_1  |[0m Traceback (most recent call last):
[36mtest-network-permissioning_1  |[0m   File "/project/sawtooth-core/bin/sawtooth-validator", line 37, in <module>
[36mtest-network-permissioning_1  |[0m     main()
[36mtest-network-permissioning_1  |[0m   File "/project/sawtooth-core/validator/sawtooth_validator/server/cli.py", line 366, in main
[36mtest-network-permissioning_1  |[0m     validator.stop()
[36mtest-network-permissioning_1  |[0m   File "/project/sawtooth-core/validator/sawtooth_validator/server/core.py", line 348, in stop
[36mtest-network-permissioning_1  |[0m     self._network_service.stop()
[36mtest-network-permissioning_1  |[0m   File "/project/sawtooth-core/validator/sawtooth_validator/networking/interconnect.py", line 977, in stop
[36mtest-network-permissioning_1  |[0m     conn.stop()
[36mtest-network-permissioning_1  |[0m   File "/project/sawtooth-core/validator/sawtooth_validator/networking/interconnect.py", line 1271, in stop
[36mtest-network-permissioning_1  |[0m     self._send_receive_thread.shutdown()
[36mtest-network-permissioning_1  |[0m   File "/project/sawtooth-core/validator/sawtooth_validator/networking/interconnect.py", line 587, in shutdown
[36mtest-network-permissioning_1  |[0m     time.sleep(.2)
[36mtest-network-permissioning_1  |[0m KeyboardInterrupt

======================================================================
FAIL: test_network_challenge_permissioning (test_network_permissioning.TestNetworkPermissioning)
Test the network "challenge" permissioning role.
----------------------------------------------------------------------
Traceback (most recent call last):
  File "/project/sawtooth-core/integration/sawtooth_integration/tests/test_network_permissioning.py", line 230, in test_network_challenge_permissioning
    processes.extend(start_validator(3, sawtooth_home1))
  File "/project/sawtooth-core/integration/sawtooth_integration/tests/test_network_permissioning.py", line 296, in start_validator
    {})
  File "/project/sawtooth-core/integration/sawtooth_integration/tests/node_controller.py", line 105, in start_node
    wait_for_rest_apis(['127.0.0.1:{}'.format(8080 + num)], tries=20)
  File "/project/sawtooth-core/integration/sawtooth_integration/tests/integration_tools.py", line 235, in wait_for_rest_apis
    tries=tries)
  File "/project/sawtooth-core/integration/sawtooth_integration/tests/integration_tools.py", line 218, in wait_until_status
    "{} is not available within {} attempts".format(url, tries))
AssertionError: http://127.0.0.1:8083/blocks is not available within 20 attempts

----------------------------------------------------------------------
Ran 2 tests in 644.446s

FAILED (failures=1)

intkey_smoke
======================================================================
ERROR: test_intkey_smoke (test_intkey_smoke.TestIntkeySmoke)
----------------------------------------------------------------------
Traceback (most recent call last):
  File "/project/sawtooth-core/integration/sawtooth_integration/tests/test_intkey_smoke.py", line 86, in test_intkey_smoke
    self.post_and_verify(batch, how_many_updates)
  File "/project/sawtooth-core/integration/sawtooth_integration/tests/test_intkey_smoke.py", line 93, in post_and_verify
    _post_batch(batch)
  File "/project/sawtooth-core/integration/sawtooth_integration/tests/test_intkey_smoke.py", line 128, in _post_batch
    response = _submit_request('{}&wait={}'.format(response['link'], WAIT))
  File "/project/sawtooth-core/integration/sawtooth_integration/tests/test_intkey_smoke.py", line 152, in _submit_request
    conn = urllib.request.urlopen(request)
  File "/usr/lib/python3.5/urllib/request.py", line 163, in urlopen
    return opener.open(url, data, timeout)
  File "/usr/lib/python3.5/urllib/request.py", line 472, in open
    response = meth(req, response)
  File "/usr/lib/python3.5/urllib/request.py", line 582, in http_response
    'http', request, response, code, msg, hdrs)
  File "/usr/lib/python3.5/urllib/request.py", line 510, in error
    return self._call_chain(*args)
  File "/usr/lib/python3.5/urllib/request.py", line 444, in _call_chain
    result = func(*args)
  File "/usr/lib/python3.5/urllib/request.py", line 590, in http_error_default
    raise HTTPError(req.full_url, code, msg, hdrs, fp)
urllib.error.HTTPError: HTTP Error 503: Service Unavailable

----------------------------------------------------------------------
